<robot name="robot">
  <link name="base_footprint"></link>
  <joint name="base_joint" type="fixed">
    <parent link="base_footprint" />
    <child link="base_link" />
    <origin xyz="0 0 0" rpy="0 0 0" />
  </joint>

  <link name="base_link">
    <visual>
      <origin xyz="0 0 0" rpy="0 0 0" />
      <geometry>
        <box size="0.243 0.196 0.1" /> </geometry>
      <material name="base_link-material">
        <color rgba="0.054480276435339814 0.15292615198613213 0.407240211891531 1" />
      </material>
    </visual>
    <collision>
      <origin xyz="0 0 0" rpy="0 0 0" />
      <geometry>
        <box size="0.243 0.196 0.1" />
      </geometry>
    </collision>
    <inertial>
      <origin xyz="0 0 0" rpy="0 0 0" />
      <mass value="0.05" />
      <inertia ixx="0.16666666666666666" ixy="0" ixz="0" iyy="0.16666666666666666" iyz="0" izz="0.16666666666666666" />
    </inertial>
  </link>

  <joint name="base_link_to_cube5" type="revolute">
    <parent link="base_link" />
    <child link="cube5" />
    <origin xyz="0.069 0.098 -0.11469792884829269" rpy="-3.141592653589793 0 -3.141592653589793" />
    <axis xyz="0 0 1"/>
    <limit effort="1000.0"  velocity="0.5"/>
  </joint>
  <link name="cube5">
    <visual>
      <origin xyz="0 0.103 0" rpy="0 0 0" />
      <geometry>
        <box size="0.036 0.206 0.125" />
      </geometry>
      <material name="cube5-material">
        <color rgba="0.7230551289161951 0.23839757380151394 0.6307571363387763 1" />
      </material>
    </visual>
    <collision>
      <origin xyz="0 0.103 0" rpy="0 0 0" />
      <geometry>
        <box size="0.036 0.206 0.125" />
      </geometry>
    </collision>
    <inertial>
      <origin xyz="0 0.103 0" rpy="0 0 0" />
      <mass value="0.05" />
      <inertia ixx="0.16666666666666666" ixy="0" ixz="0" iyy="0.16666666666666666" iyz="0" izz="0.16666666666666666" />
    </inertial>
  </link>
  <joint name="cube5_to_cube9" type="revolute">
    <parent link="cube5" />
    <child link="cube9" />
    <origin xyz="-0.048161324956420803 0.17705483565899827 0.019230531314252386" rpy="-1.570796326794897 0 1.570796326794897" />
    <axis xyz="0 0 1"/>
    <limit effort="1000.0" lower="-3.14" upper="3.14" velocity="0.5"/>
  </joint>
  <link name="cube9">
    <visual>
      <origin xyz="-2.127657382593146e-18 -0.125 0" rpy="1.5707963267948963 0 0" />
      <geometry>
        <box size="0.06 0.057 0.25" />
      </geometry>
      <material name="cube9-material">
        <color rgba="0.8631572134510892 0.6514056374127929 0.05126945836711539 1" />
      </material>
    </visual>
    <collision>
      <origin xyz="-2.127657382593146e-18 -0.125 0" rpy="1.5707963267948963 0 0" />
      <geometry>
        <box size="0.06 0.06 0.25" />
      </geometry>
    </collision>
    <inertial>
      <origin xyz="-2.127657382593146e-18 -0.125 0" rpy="0 0 0" />
      <mass value="0.05" />
      <inertia ixx="0.16666666666666666" ixy="0" ixz="0" iyy="0.16666666666666666" iyz="0" izz="0.16666666666666666" />
    </inertial>
  </link>

  <joint name="base_link_to_cube6" type="revolute">
    <parent link="base_link" />
    <child link="cube6" />
    <origin xyz="-0.1033382551226713 -0.0983866064663887 -0.11469792884829269" rpy="3.141592653589793 0 0" />
    <axis xyz="0 0 1"/>
    <limit effort="1000.0" lower="-3.14" upper="3.14" velocity="0.5"/>
  </joint>
  <link name="cube6">
    <visual>
      <origin xyz="0 0.103 0" rpy="0 0 0" />
      <geometry>
        <box size="0.036 0.206 0.125" />
      </geometry>
      <material name="cube6-material">
        <color rgba="0.7230551289161951 0.23839757380151394 0.6307571363387763 1" />
      </material>
    </visual>
    <collision>
      <origin xyz="0 0.103 0" rpy="0 0 0" />
      <geometry>
        <box size="0.036 0.206 0.125" />
      </geometry>
    </collision>
    <inertial>
      <origin xyz="0 0.103 0" rpy="0 0 0" />
      <mass value="0.05" />
      <inertia ixx="0.16666666666666666" ixy="0" ixz="0" iyy="0.16666666666666666" iyz="0" izz="0.16666666666666666" />
    </inertial>
  </link>
  <joint name="cube6_to_cube10" type="revolute">
    <parent link="cube6" />
    <child link="cube10" />
    <origin xyz="-0.048161324956420803 0.17705483565899827 0.019230531314252386" rpy="-1.5707963267948966 0 1.5707963267948963" />
    <axis xyz="0 0 1"/>
    <limit effort="1000.0" lower="-3.14" upper="3.14" velocity="0.5"/>
  </joint>
  <link name="cube10">
    <visual>
      <origin xyz="-2.127657382593146e-18 -0.125 0" rpy="1.5707963267948963 0 0" />
      <geometry>
        <box size="0.06 0.057 0.25" />
      </geometry>
      <material name="cube10-material">
        <color rgba="0.8631572134510892 0.6514056374127929 0.05126945836711539 1" />
      </material>
    </visual>
    <collision>
      <origin xyz="-2.127657382593146e-18 -0.125 0" rpy="1.5707963267948963 0 0" />
      <geometry>
        <box size="0.06 0.06 0.25" />
      </geometry>
    </collision>
    <inertial>
      <origin xyz="-2.127657382593146e-18 -0.125 0" rpy="0 0 0" />
      <mass value="0.05" />
      <inertia ixx="0.16666666666666666" ixy="0" ixz="0" iyy="0.16666666666666666" iyz="0" izz="0.16666666666666666" />
    </inertial>
  </link>

  <joint name="base_link_to_cube7" type="revolute">
    <parent link="base_link" />
    <child link="cube7" />
    <origin xyz="0.09216405792838034 -0.0977373217828965 -0.11469792884829269" rpy="3.141592653589793 0 0" />
    <axis xyz="0 0 1"/>
    <limit effort="1000.0" lower="-3.14" upper="3.14" velocity="0.5"/>
  </joint>
  <link name="cube7">
    <visual>
      <origin xyz="0 0.103 0" rpy="0 0 0" />
      <geometry>
        <box size="0.036 0.206 0.125" />
      </geometry>
      <material name="cube7-material">
        <color rgba="0.7230551289161951 0.23839757380151394 0.6307571363387763 1" />
      </material>
    </visual>
    <collision>
      <origin xyz="0 0.103 0" rpy="0 0 0" />
      <geometry>
        <box size="0.036 0.206 0.125" />
      </geometry>
    </collision>
    <inertial>
      <origin xyz="0 0.103 0" rpy="0 0 0" />
      <mass value="0.05" />
      <inertia ixx="0.16666666666666666" ixy="0" ixz="0" iyy="0.16666666666666666" iyz="0" izz="0.16666666666666666" />
    </inertial>
  </link>
  <joint name="cube7_to_cube11" type="revolute">
    <parent link="cube7" />
    <child link="cube11" />
    <origin xyz="0.04633851732690226 0.17705483565899827 0.019230531314252386" rpy="-1.5707963267948966 0 1.5707963267948963" />
    <axis xyz="0 0 1"/>
    <limit effort="1000.0" lower="-3.14" upper="3.14" velocity="0.5"/>
  </joint>
  <link name="cube11">
    <visual>
      <origin xyz="-2.127657382593146e-18 -0.125 0" rpy="1.5707963267948963 0 0" />
      <geometry>
        <box size="0.06 0.057 0.25" />
      </geometry>
      <material name="cube11-material">
        <color rgba="0.8631572134510892 0.6514056374127929 0.05126945836711539 1" />
      </material>
    </visual>
    <collision>
      <origin xyz="-2.127657382593146e-18 -0.125 0" rpy="1.5707963267948963 0 0" />
      <geometry>
        <box size="0.06 0.06 0.25" />
      </geometry>
    </collision>
    <inertial>
      <origin xyz="-2.127657382593146e-18 -0.125 0" rpy="0 0 0" />
      <mass value="0.05" />
      <inertia ixx="0.16666666666666666" ixy="0" ixz="0" iyy="0.16666666666666666" iyz="0" izz="0.16666666666666666" />
    </inertial>
  </link>

  <joint name="base_link_to_cube8" type="revolute">
    <parent link="base_link" />
    <child link="cube8" />
    <origin xyz="-0.10493619252487814 0.10058603880101953 -0.11469792884829269" rpy="-3.141592653589793 0 -3.141592653589793" />
    <axis xyz="0 0 1"/>
    <limit effort="1000.0" lower="-3.14" upper="3.14" velocity="0.5"/>
  </joint>
  <link name="cube8">
    <visual>
      <origin xyz="0 0.103 0" rpy="0 0 0" />
      <geometry>
        <box size="0.036 0.206 0.125" />
      </geometry>
      <material name="cube8-material">
        <color rgba="0.7230551289161951 0.23839757380151394 0.6307571363387763 1" />
      </material>
    </visual>
    <collision>
      <origin xyz="0 0.103 0" rpy="0 0 0" />
      <geometry>
        <box size="0.036 0.206 0.125" />
      </geometry>
    </collision>
    <inertial>
      <origin xyz="0 0.103 0" rpy="0 0 0" />
      <mass value="0.05" />
      <inertia ixx="0.16666666666666666" ixy="0" ixz="0" iyy="0.16666666666666666" iyz="0" izz="0.16666666666666666" />
    </inertial>
  </link>
  <joint name="cube8_to_cube12" type="revolute">
    <parent link="cube8" />
    <child link="cube12" />
    <origin xyz="0.04633851732690226 0.17705483565899827 0.019230531314252386" rpy="-1.5707963267948966 0 1.5707963267948963" />
    <axis xyz="0 0 1"/>
    <limit effort="1000.0" lower="-3.14" upper="3.14" velocity="0.5"/>
  </joint>
  <link name="cube12">
    <visual>
      <origin xyz="-2.127657382593146e-18 -0.125 0" rpy="1.5707963267948963 0 0" />
      <geometry>
        <box size="0.06 0.057 0.25" />
      </geometry>
      <material name="cube12-material">
        <color rgba="0.8631572134510892 0.6514056374127929 0.05126945836711539 1" />
      </material>
    </visual>
    <collision>
      <origin xyz="-2.127657382593146e-18 -0.125 0" rpy="1.5707963267948963 0 0" />
      <geometry>
        <box size="0.06 0.06 0.25" />
      </geometry>
    </collision>
    <inertial>
      <origin xyz="-2.127657382593146e-18 -0.125 0" rpy="0 0 0" />
      <mass value="0.05" />
      <inertia ixx="0.16666666666666666" ixy="0" ixz="0" iyy="0.16666666666666666" iyz="0" izz="0.16666666666666666" />
    </inertial>
  </link>

  <joint name="belly_lidar_joint" type="fixed">
    <parent link="base_link"/>
    <child link="belly_lidar_link"/>
    <origin xyz="0 0 -0.07" rpy="3.14159 0 0"/> 
  </joint>

  <link name="belly_lidar_link">
    <visual>
      <geometry><cylinder radius="0.04" length="0.04"/></geometry>
      <material name="black"><color rgba="0.1 0.1 0.1 1"/></material>
    </visual>
    <collision>
      <geometry><cylinder radius="0.04" length="0.04"/></geometry>
    </collision>
    <inertial>
      <mass value="0.05"/>
      <inertia ixx="0.0001" ixy="0" ixz="0" iyy="0.0001" iyz="0" izz="0.0001"/>
    </inertial>
  </link>

  <gazebo reference="belly_lidar_link">
    <sensor name="belly_lidar" type="gpu_lidar">
      <always_on>true</always_on>
      <visualize>true</visualize> 
      <update_rate>10</update_rate>
      <ray>
        <scan>
          <horizontal>
            <samples>360</samples>
            <resolution>1.0</resolution>
            <min_angle>-3.14159</min_angle>
            <max_angle>3.14159</max_angle>
          </horizontal>
        </scan>
        <range>
          <min>0.45</min>
          <max>10.0</max>
          <resolution>0.01</resolution>
        </range>
      </ray>
      <topic>scan</topic>
      <gz_frame_id>belly_lidar_link</gz_frame_id>
    </sensor>
  </gazebo>
  <ros2_control name="GazeboSimSystem" type="system">
    <hardware>
      <plugin>gz_ros2_control/GazeboSimSystem</plugin>
    </hardware>

    

    <joint name="base_link_to_cube5">
      <command_interface name="position"/>
      <state_interface name="position"/>
    </joint>
    <joint name="cube5_to_cube9">
      <command_interface name="position"/>
      <state_interface name="position"/>
    </joint>

    <joint name="base_link_to_cube6">
      <command_interface name="position"/>
      <state_interface name="position"/>
    </joint>
    <joint name="cube6_to_cube10">
      <command_interface name="position"/>
      <state_interface name="position"/>
    </joint>

    <joint name="base_link_to_cube7">
      <command_interface name="position"/>
      <state_interface name="position"/>
    </joint>
    <joint name="cube7_to_cube11">
      <command_interface name="position"/>
      <state_interface name="position"/>
    </joint>

    <joint name="base_link_to_cube8">
      <command_interface name="position"/>
      <state_interface name="position"/>
    </joint>
    <joint name="cube8_to_cube12">
      <command_interface name="position"/>
      <state_interface name="position"/>
    </joint>
  </ros2_control>

  <gazebo reference="cube9">
    <mu1>1.0</mu1>
    <mu2>1.0</mu2>
    <kp>1000000.0</kp>
    <kd>100.0</kd>
    <minDepth>0.001</minDepth>
  </gazebo>
  <gazebo reference="cube10">
    <mu1>1.0</mu1>
    <mu2>1.0</mu2>
    <kp>1000000.0</kp>
    <kd>100.0</kd>
    <minDepth>0.001</minDepth>
  </gazebo>
  <gazebo reference="cube11">
    <mu1>1.0</mu1>
    <mu2>1.0</mu2>
    <kp>1000000.0</kp>
    <kd>100.0</kd>
    <minDepth>0.001</minDepth>
  </gazebo>
  <gazebo reference="cube12">
    <mu1>1.0</mu1>
    <mu2>1.0</mu2>
    <kp>1000000.0</kp>
    <kd>100.0</kd>
    <minDepth>0.001</minDepth>
  </gazebo>
  <gazebo>
    <plugin filename="libgz_ros2_control-system.so" name="gz_ros2_control::GazeboSimROS2ControlPlugin">
      <parameters>$(find quadruped_basics)/config/sim_controllers.yaml</parameters>
    </plugin>
  </gazebo>
  <gazebo>
    <plugin filename="libgz-sim-sensors-system.so" name="gz::sim::systems::Sensors">
      <render_engine>ogre2</render_engine>
    </plugin>
  </gazebo>
</robot>
